{
    DataVersion: 4790,
    size: [14, 14, 14],
    data: [
        {
            pos: [6, 0, 6],
            state: "minecraft:smooth_basalt"
        },
        {
            pos: [6, 0, 7],
            state: "minecraft:smooth_basalt"
        },
        {
            pos: [6, 0, 8],
            state: "minecraft:smooth_basalt"
        },
        {
            pos: [7, 0, 6],
            state: "minecraft:smooth_basalt"
        },
        {
            pos: [7, 0, 7],
            state: "minecraft:smooth_basalt"
        },
        {
            pos: [7, 0, 8],
            state: "minecraft:smooth_basalt"
        },
        {
            pos: [8, 0, 6],
            state: "minecraft:smooth_basalt"
        },
        {
            pos: [8, 0, 7],
            state: "minecraft:smooth_basalt"
        },
        {
            pos: [3, 1, 7],
            state: "minecraft:smooth_basalt"
        },
        {
            pos: [4, 1, 5],
            state: "minecraft:smooth_basalt"
        },
        {
            pos: [4, 1, 6],
            state: "minecraft:smooth_basalt"
        },
        {
            pos: [4, 1, 7],
            state: "minecraft:smooth_basalt"
        },
        {
            pos: [4, 1, 8],
            state: "minecraft:smooth_basalt"
        },
        {
            pos: [4, 1, 9],
            state: "minecraft:smooth_basalt"
        },
        {
            pos: [5, 1, 4],
            state: "minecraft:smooth_basalt"
        },
        {
            pos: [5, 1, 5],
            state: "minecraft:smooth_basalt"
        },
        {
            pos: [5, 1, 6],
            state: "minecraft:smooth_basalt"
        },
        {
            pos: [5, 1, 7],
            state: "minecraft:calcite"
        },
        {
            pos: [5, 1, 8],
            state: "minecraft:smooth_basalt"
        },
        {
            pos: [5, 1, 9],
            state: "minecraft:smooth_basalt"
        },
        {
            pos: [5, 1, 10],
            state: "minecraft:smooth_basalt"
        },
        {
            pos: [6, 1, 4],
            state: "minecraft:smooth_basalt"
        },
        {
            pos: [6, 1, 5],
            state: "minecraft:smooth_basalt"
        },
        {
            pos: [6, 1, 6],
            state: "minecraft:calcite"
        },
        {
            pos: [6, 1, 7],
            state: "minecraft:calcite"
        },
        {
            pos: [6, 1, 8],
            state: "minecraft:calcite"
        },
        {
            pos: [6, 1, 9],
            state: "minecraft:smooth_basalt"
        },
        {
            pos: [6, 1, 10],
            state: "minecraft:smooth_basalt"
        },
        {
            pos: [7, 1, 5],
            state: "minecraft:calcite"
        },
        {
            pos: [7, 1, 6],
            state: "minecraft:calcite"
        },
        {
            pos: [7, 1, 7],
            state: "minecraft:calcite"
        },
        {
            pos: [7, 1, 8],
            state: "minecraft:calcite"
        },
        {
            pos: [7, 1, 9],
            state: "minecraft:smooth_basalt"
        },
        {
            pos: [7, 1, 10],
            state: "minecraft:smooth_basalt"
        },
        {
            pos: [8, 1, 6],
            state: "minecraft:calcite"
        },
        {
            pos: [8, 1, 7],
            state: "minecraft:calcite"
        },
        {
            pos: [8, 1, 8],
            state: "minecraft:calcite"
        },
        {
            pos: [8, 1, 9],
            state: "minecraft:smooth_basalt"
        },
        {
            pos: [8, 1, 10],
            state: "minecraft:smooth_basalt"
        },
        {
            pos: [9, 1, 5],
            state: "minecraft:smooth_basalt"
        },
        {
            pos: [9, 1, 6],
            state: "minecraft:smooth_basalt"
        },
        {
            pos: [9, 1, 7],
            state: "minecraft:smooth_basalt"
        },
        {
            pos: [9, 1, 8],
            state: "minecraft:smooth_basalt"
        },
        {
            pos: [9, 1, 9],
            state: "minecraft:smooth_basalt"
        },
        {
            pos: [10, 1, 5],
            state: "minecraft:smooth_basalt"
        },
        {
            pos: [10, 1, 6],
            state: "minecraft:smooth_basalt"
        },
        {
            pos: [10, 1, 7],
            state: "minecraft:smooth_basalt"
        },
        {
            pos: [10, 1, 8],
            state: "minecraft:smooth_basalt"
        },
        {
            pos: [2, 2, 6],
            state: "minecraft:smooth_basalt"
        },
        {
            pos: [2, 2, 7],
            state: "minecraft:smooth_basalt"
        },
        {
            pos: [2, 2, 8],
            state: "minecraft:smooth_basalt"
        },
        {
            pos: [3, 2, 4],
            state: "minecraft:smooth_basalt"
        },
        {
            pos: [3, 2, 5],
            state: "minecraft:smooth_basalt"
        },
        {
            pos: [3, 2, 6],
            state: "minecraft:smooth_basalt"
        },
        {
            pos: [3, 2, 7],
            state: "minecraft:smooth_basalt"
        },
        {
            pos: [3, 2, 8],
            state: "minecraft:smooth_basalt"
        },
        {
            pos: [3, 2, 9],
            state: "minecraft:smooth_basalt"
        },
        {
            pos: [4, 2, 4],
            state: "minecraft:smooth_basalt"
        },
        {
            pos: [4, 2, 5],
            state: "minecraft:calcite"
        },
        {
            pos: [4, 2, 6],
            state: "minecraft:calcite"
        },
        {
            pos: [4, 2, 7],
            state: "minecraft:calcite"
        },
        {
            pos: [4, 2, 8],
            state: "minecraft:calcite"
        },
        {
            pos: [4, 2, 9],
            state: "minecraft:calcite"
        },
        {
            pos: [4, 2, 10],
            state: "minecraft:smooth_basalt"
        },
        {
            pos: [5, 2, 3],
            state: "minecraft:smooth_basalt"
        },
        {
            pos: [5, 2, 4],
            state: "minecraft:calcite"
        },
        {
            pos: [5, 2, 5],
            state: "minecraft:calcite"
        },
        {
            pos: [5, 2, 6],
            state: "minecraft:calcite"
        },
        {
            pos: [5, 2, 7],
            state: "nodeworks:celestine_block"
        },
        {
            pos: [5, 2, 8],
            state: "minecraft:calcite"
        },
        {
            pos: [5, 2, 9],
            state: "minecraft:calcite"
        },
        {
            pos: [5, 2, 10],
            state: "minecraft:calcite"
        },
        {
            pos: [5, 2, 11],
            state: "minecraft:smooth_basalt"
        },
        {
            pos: [6, 2, 4],
            state: "minecraft:calcite"
        },
        {
            pos: [6, 2, 5],
            state: "minecraft:calcite"
        },
        {
            pos: [6, 2, 6],
            state: "nodeworks:celestine_block"
        },
        {
            pos: [6, 2, 7],
            state: "nodeworks:celestine_block"
        },
        {
            pos: [6, 2, 8],
            state: "nodeworks:celestine_block"
        },
        {
            pos: [6, 2, 9],
            state: "minecraft:calcite"
        },
        {
            pos: [6, 2, 10],
            state: "minecraft:calcite"
        },
        {
            pos: [6, 2, 11],
            state: "minecraft:smooth_basalt"
        },
        {
            pos: [7, 2, 6],
            state: "nodeworks:celestine_block"
        },
        {
            pos: [7, 2, 7],
            state: "nodeworks:celestine_block"
        },
        {
            pos: [7, 2, 8],
            state: "nodeworks:celestine_block"
        },
        {
            pos: [7, 2, 9],
            state: "minecraft:calcite"
        },
        {
            pos: [7, 2, 10],
            state: "minecraft:calcite"
        },
        {
            pos: [7, 2, 11],
            state: "minecraft:smooth_basalt"
        },
        {
            pos: [8, 2, 6],
            state: "nodeworks:celestine_block"
        },
        {
            pos: [8, 2, 7],
            state: "nodeworks:celestine_block"
        },
        {
            pos: [8, 2, 8],
            state: "nodeworks:celestine_block"
        },
        {
            pos: [8, 2, 9],
            state: "minecraft:calcite"
        },
        {
            pos: [8, 2, 10],
            state: "minecraft:calcite"
        },
        {
            pos: [8, 2, 11],
            state: "minecraft:smooth_basalt"
        },
        {
            pos: [9, 2, 6],
            state: "minecraft:calcite"
        },
        {
            pos: [9, 2, 7],
            state: "minecraft:calcite"
        },
        {
            pos: [9, 2, 8],
            state: "minecraft:calcite"
        },
        {
            pos: [9, 2, 9],
            state: "minecraft:calcite"
        },
        {
            pos: [9, 2, 10],
            state: "minecraft:smooth_basalt"
        },
        {
            pos: [9, 2, 11],
            state: "minecraft:smooth_basalt"
        },
        {
            pos: [10, 2, 5],
            state: "minecraft:calcite"
        },
        {
            pos: [10, 2, 6],
            state: "minecraft:calcite"
        },
        {
            pos: [10, 2, 7],
            state: "minecraft:calcite"
        },
        {
            pos: [10, 2, 8],
            state: "minecraft:calcite"
        },
        {
            pos: [10, 2, 9],
            state: "minecraft:smooth_basalt"
        },
        {
            pos: [10, 2, 10],
            state: "minecraft:smooth_basalt"
        },
        {
            pos: [11, 2, 4],
            state: "minecraft:smooth_basalt"
        },
        {
            pos: [11, 2, 5],
            state: "minecraft:smooth_basalt"
        },
        {
            pos: [11, 2, 6],
            state: "minecraft:smooth_basalt"
        },
        {
            pos: [11, 2, 7],
            state: "minecraft:smooth_basalt"
        },
        {
            pos: [11, 2, 8],
            state: "minecraft:smooth_basalt"
        },
        {
            pos: [11, 2, 9],
            state: "minecraft:smooth_basalt"
        },
        {
            pos: [1, 3, 7],
            state: "minecraft:smooth_basalt"
        },
        {
            pos: [2, 3, 4],
            state: "minecraft:smooth_basalt"
        },
        {
            pos: [2, 3, 5],
            state: "minecraft:smooth_basalt"
        },
        {
            pos: [2, 3, 6],
            state: "minecraft:smooth_basalt"
        },
        {
            pos: [2, 3, 7],
            state: "minecraft:smooth_basalt"
        },
        {
            pos: [2, 3, 8],
            state: "minecraft:smooth_basalt"
        },
        {
            pos: [2, 3, 9],
            state: "minecraft:smooth_basalt"
        },
        {
            pos: [3, 3, 3],
            state: "minecraft:smooth_basalt"
        },
        {
            pos: [3, 3, 4],
            state: "minecraft:smooth_basalt"
        },
        {
            pos: [3, 3, 5],
            state: "minecraft:calcite"
        },
        {
            pos: [3, 3, 6],
            state: "minecraft:calcite"
        },
        {
            pos: [3, 3, 7],
            state: "minecraft:calcite"
        },
        {
            pos: [3, 3, 8],
            state: "minecraft:calcite"
        },
        {
            pos: [3, 3, 9],
            state: "minecraft:calcite"
        },
        {
            pos: [3, 3, 10],
            state: "minecraft:smooth_basalt"
        },
        {
            pos: [4, 3, 3],
            state: "minecraft:smooth_basalt"
        },
        {
            pos: [4, 3, 4],
            state: "minecraft:calcite"
        },
        {
            pos: [4, 3, 5],
            state: "minecraft:calcite"
        },
        {
            pos: [4, 3, 6],
            state: "nodeworks:budding_celestine"
        },
        {
            pos: [4, 3, 7],
            state: "nodeworks:celestine_block"
        },
        {
            pos: [4, 3, 8],
            state: "nodeworks:celestine_block"
        },
        {
            pos: [4, 3, 9],
            state: "minecraft:calcite"
        },
        {
            pos: [4, 3, 10],
            state: "minecraft:calcite"
        },
        {
            pos: [4, 3, 11],
            state: "minecraft:smooth_basalt"
        },
        {
            pos: [5, 3, 2],
            state: "minecraft:smooth_basalt"
        },
        {
            pos: [5, 3, 3],
            state: "minecraft:calcite"
        },
        {
            pos: [5, 3, 4],
            state: "minecraft:calcite"
        },
        {
            pos: [5, 3, 5],
            state: "nodeworks:celestine_block"
        },
        {
            pos: [5, 3, 6],
            state: "nodeworks:budding_celestine"
        },
        {
            pos: [5, 3, 7],
            state: "nodeworks:celestine_block"
        },
        {
            pos: [5, 3, 8],
            state: "nodeworks:celestine_block"
        },
        {
            pos: [5, 3, 9],
            state: "nodeworks:budding_celestine"
        },
        {
            pos: [5, 3, 10],
            state: "minecraft:calcite"
        },
        {
            pos: [5, 3, 11],
            state: "minecraft:calcite"
        },
        {
            pos: [5, 3, 12],
            state: "minecraft:smooth_basalt"
        },
        {
            pos: [6, 3, 5],
            state: "nodeworks:celestine_block"
        },
        {
            pos: [6, 3, 8],
            state: "nodeworks:celestine_block"
        },
        {
            pos: [6, 3, 9],
            state: "nodeworks:celestine_block"
        },
        {
            pos: [6, 3, 10],
            state: "nodeworks:celestine_block"
        },
        {
            pos: [6, 3, 11],
            state: "minecraft:calcite"
        },
        {
            pos: [6, 3, 12],
            state: "minecraft:smooth_basalt"
        },
        {
            pos: [7, 3, 9],
            state: "nodeworks:budding_celestine"
        },
        {
            pos: [7, 3, 10],
            state: "nodeworks:celestine_block"
        },
        {
            pos: [7, 3, 11],
            state: "minecraft:calcite"
        },
        {
            pos: [7, 3, 12],
            state: "minecraft:smooth_basalt"
        },
        {
            pos: [8, 3, 6],
            state: "nodeworks:celestine_block"
        },
        {
            pos: [8, 3, 8],
            state: "nodeworks:celestine_block"
        },
        {
            pos: [8, 3, 9],
            state: "nodeworks:celestine_block"
        },
        {
            pos: [8, 3, 10],
            state: "nodeworks:celestine_block"
        },
        {
            pos: [8, 3, 11],
            state: "minecraft:calcite"
        },
        {
            pos: [8, 3, 12],
            state: "minecraft:smooth_basalt"
        },
        {
            pos: [9, 3, 6],
            state: "nodeworks:celestine_block"
        },
        {
            pos: [9, 3, 7],
            state: "nodeworks:celestine_block"
        },
        {
            pos: [9, 3, 8],
            state: "nodeworks:celestine_block"
        },
        {
            pos: [9, 3, 9],
            state: "nodeworks:celestine_block"
        },
        {
            pos: [9, 3, 10],
            state: "minecraft:calcite"
        },
        {
            pos: [9, 3, 11],
            state: "minecraft:calcite"
        },
        {
            pos: [9, 3, 12],
            state: "minecraft:smooth_basalt"
        },
        {
            pos: [10, 3, 6],
            state: "nodeworks:celestine_block"
        },
        {
            pos: [10, 3, 7],
            state: "nodeworks:celestine_block"
        },
        {
            pos: [10, 3, 8],
            state: "nodeworks:celestine_block"
        },
        {
            pos: [10, 3, 9],
            state: "minecraft:calcite"
        },
        {
            pos: [10, 3, 10],
            state: "minecraft:calcite"
        },
        {
            pos: [10, 3, 11],
            state: "minecraft:smooth_basalt"
        },
        {
            pos: [11, 3, 4],
            state: "minecraft:smooth_basalt"
        },
        {
            pos: [11, 3, 5],
            state: "minecraft:calcite"
        },
        {
            pos: [11, 3, 6],
            state: "minecraft:calcite"
        },
        {
            pos: [11, 3, 7],
            state: "minecraft:calcite"
        },
        {
            pos: [11, 3, 8],
            state: "minecraft:calcite"
        },
        {
            pos: [11, 3, 9],
            state: "minecraft:calcite"
        },
        {
            pos: [11, 3, 10],
            state: "minecraft:smooth_basalt"
        },
        {
            pos: [12, 3, 4],
            state: "minecraft:smooth_basalt"
        },
        {
            pos: [12, 3, 5],
            state: "minecraft:smooth_basalt"
        },
        {
            pos: [12, 3, 6],
            state: "minecraft:smooth_basalt"
        },
        {
            pos: [12, 3, 7],
            state: "minecraft:smooth_basalt"
        },
        {
            pos: [12, 3, 8],
            state: "minecraft:smooth_basalt"
        },
        {
            pos: [12, 3, 9],
            state: "minecraft:smooth_basalt"
        },
        {
            pos: [1, 4, 5],
            state: "minecraft:smooth_basalt"
        },
        {
            pos: [1, 4, 6],
            state: "minecraft:smooth_basalt"
        },
        {
            pos: [1, 4, 7],
            state: "minecraft:smooth_basalt"
        },
        {
            pos: [1, 4, 8],
            state: "minecraft:smooth_basalt"
        },
        {
            pos: [1, 4, 9],
            state: "minecraft:smooth_basalt"
        },
        {
            pos: [2, 4, 3],
            state: "minecraft:smooth_basalt"
        },
        {
            pos: [2, 4, 4],
            state: "minecraft:smooth_basalt"
        },
        {
            pos: [2, 4, 5],
            state: "minecraft:calcite"
        },
        {
            pos: [2, 4, 6],
            state: "minecraft:calcite"
        },
        {
            pos: [2, 4, 7],
            state: "minecraft:calcite"
        },
        {
            pos: [2, 4, 8],
            state: "minecraft:calcite"
        },
        {
            pos: [2, 4, 9],
            state: "minecraft:calcite"
        },
        {
            pos: [2, 4, 10],
            state: "minecraft:smooth_basalt"
        },
        {
            pos: [3, 4, 3],
            state: "minecraft:smooth_basalt"
        },
        {
            pos: [3, 4, 4],
            state: "minecraft:calcite"
        },
        {
            pos: [3, 4, 5],
            state: "nodeworks:celestine_block"
        },
        {
            pos: [3, 4, 6],
            state: "nodeworks:celestine_block"
        },
        {
            pos: [3, 4, 7],
            state: "nodeworks:celestine_block"
        },
        {
            pos: [3, 4, 8],
            state: "nodeworks:celestine_block"
        },
        {
            pos: [3, 4, 9],
            state: "minecraft:calcite"
        },
        {
            pos: [3, 4, 10],
            state: "minecraft:calcite"
        },
        {
            pos: [3, 4, 11],
            state: "minecraft:smooth_basalt"
        },
        {
            pos: [4, 4, 2],
            state: "minecraft:smooth_basalt"
        },
        {
            pos: [4, 4, 3],
            state: "minecraft:calcite"
        },
        {
            pos: [4, 4, 4],
            state: "nodeworks:celestine_block"
        },
        {
            pos: [4, 4, 5],
            state: "nodeworks:celestine_block"
        },
        {
            pos: [4, 4, 6],
            state: "nodeworks:celestine_block"
        },
        {
            pos: [4, 4, 8],
            state: "nodeworks:celestine_block"
        },
        {
            pos: [4, 4, 9],
            state: "nodeworks:celestine_block"
        },
        {
            pos: [4, 4, 10],
            state: "nodeworks:celestine_block"
        },
        {
            pos: [4, 4, 11],
            state: "minecraft:calcite"
        },
        {
            pos: [4, 4, 12],
            state: "minecraft:smooth_basalt"
        },
        {
            pos: [5, 4, 2],
            state: "minecraft:calcite"
        },
        {
            pos: [5, 4, 4],
            state: "nodeworks:celestine_block"
        },
        {
            pos: [5, 4, 10],
            state: "nodeworks:celestine_block"
        },
        {
            pos: [5, 4, 11],
            state: "minecraft:calcite"
        },
        {
            pos: [5, 4, 12],
            state: "minecraft:smooth_basalt"
        },
        {
            pos: [6, 4, 10],
            state: "nodeworks:celestine_block"
        },
        {
            pos: [6, 4, 11],
            state: "nodeworks:celestine_block"
        },
        {
            pos: [6, 4, 12],
            state: "minecraft:calcite"
        },
        {
            pos: [6, 4, 13],
            state: "minecraft:smooth_basalt"
        },
        {
            pos: [7, 4, 10],
            state: "nodeworks:celestine_block"
        },
        {
            pos: [7, 4, 11],
            state: "nodeworks:celestine_block"
        },
        {
            pos: [7, 4, 12],
            state: "minecraft:calcite"
        },
        {
            pos: [7, 4, 13],
            state: "minecraft:smooth_basalt"
        },
        {
            pos: [8, 4, 10],
            state: "nodeworks:celestine_block"
        },
        {
            pos: [8, 4, 11],
            state: "minecraft:calcite"
        },
        {
            pos: [8, 4, 12],
            state: "minecraft:calcite"
        },
        {
            pos: [8, 4, 13],
            state: "minecraft:smooth_basalt"
        },
        {
            pos: [9, 4, 9],
            state: "nodeworks:celestine_block"
        },
        {
            pos: [9, 4, 10],
            state: "nodeworks:celestine_block"
        },
        {
            pos: [9, 4, 11],
            state: "minecraft:calcite"
        },
        {
            pos: [9, 4, 12],
            state: "minecraft:smooth_basalt"
        },
        {
            pos: [10, 4, 6],
            state: "nodeworks:celestine_block"
        },
        {
            pos: [10, 4, 7],
            state: "nodeworks:celestine_block"
        },
        {
            pos: [10, 4, 8],
            state: "nodeworks:celestine_block"
        },
        {
            pos: [10, 4, 9],
            state: "nodeworks:celestine_block"
        },
        {
            pos: [10, 4, 10],
            state: "minecraft:calcite"
        },
        {
            pos: [10, 4, 11],
            state: "minecraft:calcite"
        },
        {
            pos: [10, 4, 12],
            state: "minecraft:smooth_basalt"
        },
        {
            pos: [11, 4, 5],
            state: "minecraft:calcite"
        },
        {
            pos: [11, 4, 6],
            state: "nodeworks:celestine_block"
        },
        {
            pos: [11, 4, 7],
            state: "nodeworks:celestine_block"
        },
        {
            pos: [11, 4, 8],
            state: "minecraft:calcite"
        },
        {
            pos: [11, 4, 9],
            state: "minecraft:calcite"
        },
        {
            pos: [11, 4, 10],
            state: "minecraft:calcite"
        },
        {
            pos: [11, 4, 11],
            state: "minecraft:smooth_basalt"
        },
        {
            pos: [12, 4, 3],
            state: "minecraft:smooth_basalt"
        },
        {
            pos: [12, 4, 4],
            state: "minecraft:smooth_basalt"
        },
        {
            pos: [12, 4, 5],
            state: "minecraft:calcite"
        },
        {
            pos: [12, 4, 6],
            state: "minecraft:calcite"
        },
        {
            pos: [12, 4, 7],
            state: "minecraft:calcite"
        },
        {
            pos: [12, 4, 8],
            state: "minecraft:calcite"
        },
        {
            pos: [12, 4, 9],
            state: "minecraft:smooth_basalt"
        },
        {
            pos: [12, 4, 10],
            state: "minecraft:smooth_basalt"
        },
        {
            pos: [13, 4, 5],
            state: "minecraft:smooth_basalt"
        },
        {
            pos: [13, 4, 6],
            state: "minecraft:smooth_basalt"
        },
        {
            pos: [13, 4, 7],
            state: "minecraft:smooth_basalt"
        },
        {
            pos: [13, 4, 8],
            state: "minecraft:smooth_basalt"
        },
        {
            pos: [1, 5, 4],
            state: "minecraft:smooth_basalt"
        },
        {
            pos: [1, 5, 5],
            state: "minecraft:smooth_basalt"
        },
        {
            pos: [1, 5, 6],
            state: "minecraft:calcite"
        },
        {
            pos: [1, 5, 7],
            state: "minecraft:calcite"
        },
        {
            pos: [1, 5, 8],
            state: "minecraft:smooth_basalt"
        },
        {
            pos: [1, 5, 9],
            state: "minecraft:smooth_basalt"
        },
        {
            pos: [1, 5, 10],
            state: "minecraft:smooth_basalt"
        },
        {
            pos: [2, 5, 3],
            state: "minecraft:smooth_basalt"
        },
        {
            pos: [2, 5, 4],
            state: "minecraft:calcite"
        },
        {
            pos: [2, 5, 5],
            state: "minecraft:calcite"
        },
        {
            pos: [2, 5, 6],
            state: "minecraft:calcite"
        },
        {
            pos: [2, 5, 7],
            state: "nodeworks:celestine_block"
        },
        {
            pos: [2, 5, 8],
            state: "minecraft:calcite"
        },
        {
            pos: [2, 5, 9],
            state: "minecraft:calcite"
        },
        {
            pos: [2, 5, 10],
            state: "minecraft:calcite"
        },
        {
            pos: [2, 5, 11],
            state: "minecraft:smooth_basalt"
        },
        {
            pos: [3, 5, 2],
            state: "minecraft:smooth_basalt"
        },
        {
            pos: [3, 5, 3],
            state: "minecraft:calcite"
        },
        {
            pos: [3, 5, 4],
            state: "minecraft:calcite"
        },
        {
            pos: [3, 5, 5],
            state: "nodeworks:celestine_block"
        },
        {
            pos: [3, 5, 6],
            state: "nodeworks:celestine_block"
        },
        {
            pos: [3, 5, 7],
            state: "nodeworks:celestine_block"
        },
        {
            pos: [3, 5, 8],
            state: "nodeworks:celestine_block"
        },
        {
            pos: [3, 5, 9],
            state: "nodeworks:celestine_block"
        },
        {
            pos: [3, 5, 10],
            state: "minecraft:calcite"
        },
        {
            pos: [3, 5, 11],
            state: "minecraft:calcite"
        },
        {
            pos: [3, 5, 12],
            state: "minecraft:smooth_basalt"
        },
        {
            pos: [4, 5, 1],
            state: "minecraft:smooth_basalt"
        },
        {
            pos: [4, 5, 2],
            state: "minecraft:calcite"
        },
        {
            pos: [4, 5, 3],
            state: "minecraft:calcite"
        },
        {
            pos: [4, 5, 4],
            state: "nodeworks:celestine_block"
        },
        {
            pos: [4, 5, 10],
            state: "nodeworks:celestine_block"
        },
        {
            pos: [4, 5, 11],
            state: "minecraft:calcite"
        },
        {
            pos: [4, 5, 12],
            state: "minecraft:smooth_basalt"
        },
        {
            pos: [5, 5, 1],
            state: "minecraft:smooth_basalt"
        },
        {
            pos: [5, 5, 10],
            state: "nodeworks:celestine_block"
        },
        {
            pos: [5, 5, 11],
            state: "nodeworks:budding_celestine"
        },
        {
            pos: [5, 5, 12],
            state: "minecraft:calcite"
        },
        {
            pos: [5, 5, 13],
            state: "minecraft:smooth_basalt"
        },
        {
            pos: [6, 5, 11],
            state: "nodeworks:celestine_block"
        },
        {
            pos: [6, 5, 12],
            state: "minecraft:calcite"
        },
        {
            pos: [6, 5, 13],
            state: "minecraft:smooth_basalt"
        },
        {
            pos: [7, 5, 11],
            state: "nodeworks:budding_celestine"
        },
        {
            pos: [7, 5, 12],
            state: "minecraft:calcite"
        },
        {
            pos: [7, 5, 13],
            state: "minecraft:smooth_basalt"
        },
        {
            pos: [8, 5, 11],
            state: "nodeworks:celestine_block"
        },
        {
            pos: [8, 5, 12],
            state: "minecraft:calcite"
        },
        {
            pos: [8, 5, 13],
            state: "minecraft:smooth_basalt"
        },
        {
            pos: [9, 5, 10],
            state: "nodeworks:celestine_block"
        },
        {
            pos: [9, 5, 11],
            state: "nodeworks:celestine_block"
        },
        {
            pos: [9, 5, 12],
            state: "minecraft:calcite"
        },
        {
            pos: [9, 5, 13],
            state: "minecraft:smooth_basalt"
        },
        {
            pos: [10, 5, 9],
            state: "nodeworks:budding_celestine"
        },
        {
            pos: [10, 5, 10],
            state: "nodeworks:celestine_block"
        },
        {
            pos: [10, 5, 11],
            state: "minecraft:calcite"
        },
        {
            pos: [10, 5, 12],
            state: "minecraft:smooth_basalt"
        },
        {
            pos: [11, 5, 5],
            state: "nodeworks:celestine_block"
        },
        {
            pos: [11, 5, 6],
            state: "nodeworks:celestine_block"
        },
        {
            pos: [11, 5, 7],
            state: "nodeworks:celestine_block"
        },
        {
            pos: [11, 5, 8],
            state: "nodeworks:celestine_block"
        },
        {
            pos: [11, 5, 9],
            state: "minecraft:calcite"
        },
        {
            pos: [11, 5, 10],
            state: "minecraft:calcite"
        },
        {
            pos: [11, 5, 11],
            state: "minecraft:smooth_basalt"
        },
        {
            pos: [11, 5, 12],
            state: "minecraft:smooth_basalt"
        },
        {
            pos: [12, 5, 2],
            state: "minecraft:smooth_basalt"
        },
        {
            pos: [12, 5, 3],
            state: "minecraft:smooth_basalt"
        },
        {
            pos: [12, 5, 4],
            state: "minecraft:calcite"
        },
        {
            pos: [12, 5, 5],
            state: "minecraft:calcite"
        },
        {
            pos: [12, 5, 6],
            state: "minecraft:calcite"
        },
        {
            pos: [12, 5, 7],
            state: "minecraft:calcite"
        },
        {
            pos: [12, 5, 8],
            state: "minecraft:calcite"
        },
        {
            pos: [12, 5, 9],
            state: "minecraft:calcite"
        },
        {
            pos: [12, 5, 10],
            state: "minecraft:smooth_basalt"
        },
        {
            pos: [12, 5, 11],
            state: "minecraft:smooth_basalt"
        },
        {
            pos: [13, 5, 4],
            state: "minecraft:smooth_basalt"
        },
        {
            pos: [13, 5, 5],
            state: "minecraft:smooth_basalt"
        },
        {
            pos: [13, 5, 6],
            state: "minecraft:smooth_basalt"
        },
        {
            pos: [13, 5, 7],
            state: "minecraft:smooth_basalt"
        },
        {
            pos: [13, 5, 8],
            state: "minecraft:smooth_basalt"
        },
        {
            pos: [13, 5, 9],
            state: "minecraft:smooth_basalt"
        },
        {
            pos: [0, 6, 6],
            state: "minecraft:smooth_basalt"
        },
        {
            pos: [0, 6, 7],
            state: "minecraft:smooth_basalt"
        },
        {
            pos: [0, 6, 8],
            state: "minecraft:smooth_basalt"
        },
        {
            pos: [1, 6, 3],
            state: "minecraft:smooth_basalt"
        },
        {
            pos: [1, 6, 4],
            state: "minecraft:smooth_basalt"
        },
        {
            pos: [1, 6, 5],
            state: "minecraft:calcite"
        },
        {
            pos: [1, 6, 6],
            state: "minecraft:calcite"
        },
        {
            pos: [1, 6, 7],
            state: "minecraft:calcite"
        },
        {
            pos: [1, 6, 8],
            state: "minecraft:calcite"
        },
        {
            pos: [1, 6, 9],
            state: "minecraft:smooth_basalt"
        },
        {
            pos: [1, 6, 10],
            state: "minecraft:smooth_basalt"
        },
        {
            pos: [2, 6, 2],
            state: "minecraft:smooth_basalt"
        },
        {
            pos: [2, 6, 3],
            state: "minecraft:smooth_basalt"
        },
        {
            pos: [2, 6, 4],
            state: "minecraft:calcite"
        },
        {
            pos: [2, 6, 5],
            state: "minecraft:calcite"
        },
        {
            pos: [2, 6, 6],
            state: "nodeworks:celestine_block"
        },
        {
            pos: [2, 6, 7],
            state: "nodeworks:celestine_block"
        },
        {
            pos: [2, 6, 8],
            state: "nodeworks:celestine_block"
        },
        {
            pos: [2, 6, 9],
            state: "minecraft:calcite"
        },
        {
            pos: [2, 6, 10],
            state: "minecraft:calcite"
        },
        {
            pos: [2, 6, 11],
            state: "minecraft:smooth_basalt"
        },
        {
            pos: [3, 6, 2],
            state: "minecraft:smooth_basalt"
        },
        {
            pos: [3, 6, 3],
            state: "minecraft:calcite"
        },
        {
            pos: [3, 6, 4],
            state: "nodeworks:celestine_block"
        },
        {
            pos: [3, 6, 5],
            state: "nodeworks:celestine_block"
        },
        {
            pos: [3, 6, 9],
            state: "nodeworks:celestine_block"
        },
        {
            pos: [3, 6, 10],
            state: "nodeworks:celestine_block"
        },
        {
            pos: [3, 6, 11],
            state: "minecraft:calcite"
        },
        {
            pos: [3, 6, 12],
            state: "minecraft:smooth_basalt"
        },
        {
            pos: [4, 6, 1],
            state: "minecraft:smooth_basalt"
        },
        {
            pos: [4, 6, 2],
            state: "minecraft:calcite"
        },
        {
            pos: [4, 6, 3],
            state: "nodeworks:celestine_block"
        },
        {
            pos: [4, 6, 4],
            state: "nodeworks:celestine_block"
        },
        {
            pos: [4, 6, 10],
            state: "nodeworks:celestine_block"
        },
        {
            pos: [4, 6, 11],
            state: "nodeworks:celestine_block"
        },
        {
            pos: [4, 6, 12],
            state: "minecraft:calcite"
        },
        {
            pos: [5, 6, 11],
            state: "nodeworks:celestine_block"
        },
        {
            pos: [5, 6, 12],
            state: "minecraft:calcite"
        },
        {
            pos: [5, 6, 13],
            state: "minecraft:smooth_basalt"
        },
        {
            pos: [6, 6, 11],
            state: "nodeworks:celestine_block"
        },
        {
            pos: [6, 6, 12],
            state: "minecraft:calcite"
        },
        {
            pos: [6, 6, 13],
            state: "minecraft:smooth_basalt"
        },
        {
            pos: [7, 6, 11],
            state: "nodeworks:celestine_block"
        },
        {
            pos: [7, 6, 12],
            state: "minecraft:calcite"
        },
        {
            pos: [7, 6, 13],
            state: "minecraft:smooth_basalt"
        },
        {
            pos: [8, 6, 11],
            state: "nodeworks:celestine_block"
        },
        {
            pos: [8, 6, 12],
            state: "minecraft:calcite"
        },
        {
            pos: [8, 6, 13],
            state: "minecraft:smooth_basalt"
        },
        {
            pos: [9, 6, 10],
            state: "nodeworks:celestine_block"
        },
        {
            pos: [9, 6, 11],
            state: "nodeworks:celestine_block"
        },
        {
            pos: [9, 6, 12],
            state: "minecraft:calcite"
        },
        {
            pos: [9, 6, 13],
            state: "minecraft:smooth_basalt"
        },
        {
            pos: [10, 6, 9],
            state: "nodeworks:celestine_block"
        },
        {
            pos: [10, 6, 10],
            state: "nodeworks:celestine_block"
        },
        {
            pos: [10, 6, 11],
            state: "minecraft:calcite"
        },
        {
            pos: [10, 6, 12],
            state: "minecraft:smooth_basalt"
        },
        {
            pos: [11, 6, 6],
            state: "nodeworks:celestine_block"
        },
        {
            pos: [11, 6, 7],
            state: "nodeworks:celestine_block"
        },
        {
            pos: [11, 6, 8],
            state: "nodeworks:celestine_block"
        },
        {
            pos: [11, 6, 9],
            state: "nodeworks:celestine_block"
        },
        {
            pos: [11, 6, 10],
            state: "minecraft:calcite"
        },
        {
            pos: [11, 6, 11],
            state: "minecraft:smooth_basalt"
        },
        {
            pos: [11, 6, 12],
            state: "minecraft:smooth_basalt"
        },
        {
            pos: [12, 6, 2],
            state: "minecraft:smooth_basalt"
        },
        {
            pos: [12, 6, 3],
            state: "minecraft:smooth_basalt"
        },
        {
            pos: [12, 6, 4],
            state: "minecraft:calcite"
        },
        {
            pos: [12, 6, 5],
            state: "minecraft:calcite"
        },
        {
            pos: [12, 6, 6],
            state: "minecraft:calcite"
        },
        {
            pos: [12, 6, 7],
            state: "minecraft:calcite"
        },
        {
            pos: [12, 6, 8],
            state: "minecraft:calcite"
        },
        {
            pos: [12, 6, 9],
            state: "minecraft:calcite"
        },
        {
            pos: [12, 6, 10],
            state: "minecraft:smooth_basalt"
        },
        {
            pos: [13, 6, 3],
            state: "minecraft:smooth_basalt"
        },
        {
            pos: [13, 6, 4],
            state: "minecraft:smooth_basalt"
        },
        {
            pos: [13, 6, 5],
            state: "minecraft:smooth_basalt"
        },
        {
            pos: [13, 6, 6],
            state: "minecraft:smooth_basalt"
        },
        {
            pos: [13, 6, 7],
            state: "minecraft:smooth_basalt"
        },
        {
            pos: [13, 6, 8],
            state: "minecraft:smooth_basalt"
        },
        {
            pos: [13, 6, 9],
            state: "minecraft:smooth_basalt"
        },
        {
            pos: [0, 7, 5],
            state: "minecraft:smooth_basalt"
        },
        {
            pos: [0, 7, 6],
            state: "minecraft:smooth_basalt"
        },
        {
            pos: [0, 7, 7],
            state: "minecraft:smooth_basalt"
        },
        {
            pos: [0, 7, 8],
            state: "minecraft:smooth_basalt"
        },
        {
            pos: [1, 7, 3],
            state: "minecraft:smooth_basalt"
        },
        {
            pos: [1, 7, 4],
            state: "minecraft:smooth_basalt"
        },
        {
            pos: [1, 7, 5],
            state: "minecraft:calcite"
        },
        {
            pos: [1, 7, 6],
            state: "minecraft:calcite"
        },
        {
            pos: [1, 7, 7],
            state: "minecraft:calcite"
        },
        {
            pos: [1, 7, 8],
            state: "minecraft:calcite"
        },
        {
            pos: [1, 7, 9],
            state: "minecraft:smooth_basalt"
        },
        {
            pos: [1, 7, 10],
            state: "minecraft:smooth_basalt"
        },
        {
            pos: [2, 7, 2],
            state: "minecraft:smooth_basalt"
        },
        {
            pos: [2, 7, 3],
            state: "minecraft:smooth_basalt"
        },
        {
            pos: [2, 7, 4],
            state: "minecraft:calcite"
        },
        {
            pos: [2, 7, 5],
            state: "minecraft:calcite"
        },
        {
            pos: [2, 7, 6],
            state: "nodeworks:celestine_block"
        },
        {
            pos: [2, 7, 7],
            state: "nodeworks:celestine_block"
        },
        {
            pos: [2, 7, 8],
            state: "nodeworks:celestine_block"
        },
        {
            pos: [2, 7, 9],
            state: "minecraft:calcite"
        },
        {
            pos: [2, 7, 10],
            state: "minecraft:calcite"
        },
        {
            pos: [2, 7, 11],
            state: "minecraft:smooth_basalt"
        },
        {
            pos: [3, 7, 2],
            state: "minecraft:smooth_basalt"
        },
        {
            pos: [3, 7, 3],
            state: "minecraft:calcite"
        },
        {
            pos: [3, 7, 4],
            state: "nodeworks:celestine_block"
        },
        {
            pos: [3, 7, 5],
            state: "nodeworks:celestine_block"
        },
        {
            pos: [3, 7, 9],
            state: "nodeworks:celestine_block"
        },
        {
            pos: [3, 7, 10],
            state: "nodeworks:celestine_block"
        },
        {
            pos: [3, 7, 11],
            state: "minecraft:calcite"
        },
        {
            pos: [3, 7, 12],
            state: "minecraft:smooth_basalt"
        },
        {
            pos: [4, 7, 1],
            state: "minecraft:smooth_basalt"
        },
        {
            pos: [4, 7, 2],
            state: "minecraft:calcite"
        },
        {
            pos: [4, 7, 3],
            state: "nodeworks:celestine_block"
        },
        {
            pos: [4, 7, 4],
            state: "nodeworks:celestine_block"
        },
        {
            pos: [4, 7, 10],
            state: "nodeworks:celestine_block"
        },
        {
            pos: [4, 7, 11],
            state: "nodeworks:celestine_block"
        },
        {
            pos: [4, 7, 12],
            state: "minecraft:calcite"
        },
        {
            pos: [4, 7, 13],
            state: "minecraft:smooth_basalt"
        },
        {
            pos: [5, 7, 11],
            state: "nodeworks:celestine_block"
        },
        {
            pos: [5, 7, 12],
            state: "minecraft:calcite"
        },
        {
            pos: [5, 7, 13],
            state: "minecraft:smooth_basalt"
        },
        {
            pos: [6, 7, 11],
            state: "nodeworks:celestine_block"
        },
        {
            pos: [6, 7, 12],
            state: "minecraft:calcite"
        },
        {
            pos: [6, 7, 13],
            state: "minecraft:smooth_basalt"
        },
        {
            pos: [7, 7, 11],
            state: "nodeworks:celestine_block"
        },
        {
            pos: [7, 7, 12],
            state: "minecraft:calcite"
        },
        {
            pos: [7, 7, 13],
            state: "minecraft:smooth_basalt"
        },
        {
            pos: [8, 7, 11],
            state: "nodeworks:celestine_block"
        },
        {
            pos: [8, 7, 12],
            state: "minecraft:calcite"
        },
        {
            pos: [8, 7, 13],
            state: "minecraft:smooth_basalt"
        },
        {
            pos: [9, 7, 10],
            state: "nodeworks:celestine_block"
        },
        {
            pos: [9, 7, 11],
            state: "nodeworks:celestine_block"
        },
        {
            pos: [9, 7, 12],
            state: "minecraft:calcite"
        },
        {
            pos: [9, 7, 13],
            state: "minecraft:smooth_basalt"
        },
        {
            pos: [10, 7, 9],
            state: "nodeworks:celestine_block"
        },
        {
            pos: [10, 7, 10],
            state: "nodeworks:celestine_block"
        },
        {
            pos: [10, 7, 11],
            state: "minecraft:calcite"
        },
        {
            pos: [10, 7, 12],
            state: "minecraft:smooth_basalt"
        },
        {
            pos: [11, 7, 6],
            state: "nodeworks:celestine_block"
        },
        {
            pos: [11, 7, 7],
            state: "nodeworks:celestine_block"
        },
        {
            pos: [11, 7, 8],
            state: "nodeworks:celestine_block"
        },
        {
            pos: [11, 7, 9],
            state: "nodeworks:celestine_block"
        },
        {
            pos: [11, 7, 10],
            state: "minecraft:calcite"
        },
        {
            pos: [11, 7, 11],
            state: "minecraft:smooth_basalt"
        },
        {
            pos: [12, 7, 2],
            state: "minecraft:smooth_basalt"
        },
        {
            pos: [12, 7, 3],
            state: "minecraft:smooth_basalt"
        },
        {
            pos: [12, 7, 4],
            state: "minecraft:calcite"
        },
        {
            pos: [12, 7, 5],
            state: "minecraft:calcite"
        },
        {
            pos: [12, 7, 6],
            state: "minecraft:calcite"
        },
        {
            pos: [12, 7, 7],
            state: "minecraft:calcite"
        },
        {
            pos: [12, 7, 8],
            state: "minecraft:calcite"
        },
        {
            pos: [12, 7, 9],
            state: "minecraft:calcite"
        },
        {
            pos: [12, 7, 10],
            state: "minecraft:smooth_basalt"
        },
        {
            pos: [13, 7, 3],
            state: "minecraft:smooth_basalt"
        },
        {
            pos: [13, 7, 4],
            state: "minecraft:smooth_basalt"
        },
        {
            pos: [13, 7, 5],
            state: "minecraft:smooth_basalt"
        },
        {
            pos: [13, 7, 6],
            state: "minecraft:smooth_basalt"
        },
        {
            pos: [13, 7, 7],
            state: "minecraft:smooth_basalt"
        },
        {
            pos: [13, 7, 8],
            state: "minecraft:smooth_basalt"
        },
        {
            pos: [13, 7, 9],
            state: "minecraft:smooth_basalt"
        },
        {
            pos: [0, 8, 6],
            state: "minecraft:smooth_basalt"
        },
        {
            pos: [0, 8, 7],
            state: "minecraft:smooth_basalt"
        },
        {
            pos: [0, 8, 8],
            state: "minecraft:smooth_basalt"
        },
        {
            pos: [1, 8, 3],
            state: "minecraft:smooth_basalt"
        },
        {
            pos: [1, 8, 4],
            state: "minecraft:smooth_basalt"
        },
        {
            pos: [1, 8, 5],
            state: "minecraft:smooth_basalt"
        },
        {
            pos: [1, 8, 6],
            state: "minecraft:calcite"
        },
        {
            pos: [1, 8, 7],
            state: "minecraft:calcite"
        },
        {
            pos: [1, 8, 8],
            state: "minecraft:calcite"
        },
        {
            pos: [1, 8, 9],
            state: "minecraft:smooth_basalt"
        },
        {
            pos: [1, 8, 10],
            state: "minecraft:smooth_basalt"
        },
        {
            pos: [2, 8, 2],
            state: "minecraft:smooth_basalt"
        },
        {
            pos: [2, 8, 3],
            state: "minecraft:smooth_basalt"
        },
        {
            pos: [2, 8, 4],
            state: "minecraft:calcite"
        },
        {
            pos: [2, 8, 5],
            state: "minecraft:calcite"
        },
        {
            pos: [2, 8, 6],
            state: "nodeworks:celestine_block"
        },
        {
            pos: [2, 8, 7],
            state: "nodeworks:celestine_block"
        },
        {
            pos: [2, 8, 8],
            state: "nodeworks:celestine_block"
        },
        {
            pos: [2, 8, 9],
            state: "minecraft:calcite"
        },
        {
            pos: [2, 8, 10],
            state: "minecraft:calcite"
        },
        {
            pos: [2, 8, 11],
            state: "minecraft:smooth_basalt"
        },
        {
            pos: [3, 8, 2],
            state: "minecraft:smooth_basalt"
        },
        {
            pos: [3, 8, 3],
            state: "minecraft:calcite"
        },
        {
            pos: [3, 8, 4],
            state: "nodeworks:celestine_block"
        },
        {
            pos: [3, 8, 5],
            state: "nodeworks:celestine_block"
        },
        {
            pos: [3, 8, 6],
            state: "nodeworks:celestine_block"
        },
        {
            pos: [3, 8, 8],
            state: "nodeworks:celestine_block"
        },
        {
            pos: [3, 8, 9],
            state: "nodeworks:celestine_block"
        },
        {
            pos: [3, 8, 10],
            state: "nodeworks:celestine_block"
        },
        {
            pos: [3, 8, 11],
            state: "minecraft:calcite"
        },
        {
            pos: [3, 8, 12],
            state: "minecraft:smooth_basalt"
        },
        {
            pos: [4, 8, 1],
            state: "minecraft:smooth_basalt"
        },
        {
            pos: [4, 8, 2],
            state: "minecraft:calcite"
        },
        {
            pos: [4, 8, 3],
            state: "nodeworks:celestine_block"
        },
        {
            pos: [4, 8, 4],
            state: "nodeworks:celestine_block"
        },
        {
            pos: [4, 8, 10],
            state: "nodeworks:celestine_block"
        },
        {
            pos: [4, 8, 11],
            state: "minecraft:calcite"
        },
        {
            pos: [4, 8, 12],
            state: "minecraft:calcite"
        },
        {
            pos: [4, 8, 13],
            state: "minecraft:smooth_basalt"
        },
        {
            pos: [5, 8, 11],
            state: "nodeworks:budding_celestine"
        },
        {
            pos: [5, 8, 12],
            state: "minecraft:calcite"
        },
        {
            pos: [5, 8, 13],
            state: "minecraft:smooth_basalt"
        },
        {
            pos: [6, 8, 11],
            state: "nodeworks:celestine_block"
        },
        {
            pos: [6, 8, 12],
            state: "minecraft:calcite"
        },
        {
            pos: [6, 8, 13],
            state: "minecraft:smooth_basalt"
        },
        {
            pos: [7, 8, 11],
            state: "nodeworks:budding_celestine"
        },
        {
            pos: [7, 8, 12],
            state: "minecraft:calcite"
        },
        {
            pos: [7, 8, 13],
            state: "minecraft:smooth_basalt"
        },
        {
            pos: [8, 8, 11],
            state: "nodeworks:celestine_block"
        },
        {
            pos: [8, 8, 12],
            state: "minecraft:calcite"
        },
        {
            pos: [8, 8, 13],
            state: "minecraft:smooth_basalt"
        },
        {
            pos: [9, 8, 10],
            state: "nodeworks:celestine_block"
        },
        {
            pos: [9, 8, 11],
            state: "minecraft:calcite"
        },
        {
            pos: [9, 8, 12],
            state: "minecraft:smooth_basalt"
        },
        {
            pos: [10, 8, 9],
            state: "nodeworks:celestine_block"
        },
        {
            pos: [10, 8, 10],
            state: "nodeworks:celestine_block"
        },
        {
            pos: [10, 8, 11],
            state: "minecraft:calcite"
        },
        {
            pos: [10, 8, 12],
            state: "minecraft:smooth_basalt"
        },
        {
            pos: [11, 8, 6],
            state: "nodeworks:celestine_block"
        },
        {
            pos: [11, 8, 7],
            state: "nodeworks:celestine_block"
        },
        {
            pos: [11, 8, 8],
            state: "nodeworks:celestine_block"
        },
        {
            pos: [11, 8, 9],
            state: "minecraft:calcite"
        },
        {
            pos: [11, 8, 10],
            state: "minecraft:calcite"
        },
        {
            pos: [11, 8, 11],
            state: "minecraft:smooth_basalt"
        },
        {
            pos: [12, 8, 2],
            state: "minecraft:smooth_basalt"
        },
        {
            pos: [12, 8, 3],
            state: "minecraft:smooth_basalt"
        },
        {
            pos: [12, 8, 4],
            state: "minecraft:calcite"
        },
        {
            pos: [12, 8, 5],
            state: "minecraft:calcite"
        },
        {
            pos: [12, 8, 6],
            state: "minecraft:calcite"
        },
        {
            pos: [12, 8, 7],
            state: "minecraft:calcite"
        },
        {
            pos: [12, 8, 8],
            state: "minecraft:calcite"
        },
        {
            pos: [12, 8, 9],
            state: "minecraft:smooth_basalt"
        },
        {
            pos: [12, 8, 10],
            state: "minecraft:smooth_basalt"
        },
        {
            pos: [13, 8, 4],
            state: "minecraft:smooth_basalt"
        },
        {
            pos: [13, 8, 5],
            state: "minecraft:smooth_basalt"
        },
        {
            pos: [13, 8, 6],
            state: "minecraft:smooth_basalt"
        },
        {
            pos: [13, 8, 7],
            state: "minecraft:smooth_basalt"
        },
        {
            pos: [13, 8, 8],
            state: "minecraft:smooth_basalt"
        },
        {
            pos: [1, 9, 4],
            state: "minecraft:smooth_basalt"
        },
        {
            pos: [1, 9, 5],
            state: "minecraft:smooth_basalt"
        },
        {
            pos: [1, 9, 6],
            state: "minecraft:smooth_basalt"
        },
        {
            pos: [1, 9, 7],
            state: "minecraft:smooth_basalt"
        },
        {
            pos: [1, 9, 8],
            state: "minecraft:smooth_basalt"
        },
        {
            pos: [1, 9, 9],
            state: "minecraft:smooth_basalt"
        },
        {
            pos: [1, 9, 10],
            state: "minecraft:smooth_basalt"
        },
        {
            pos: [2, 9, 3],
            state: "minecraft:smooth_basalt"
        },
        {
            pos: [2, 9, 4],
            state: "minecraft:calcite"
        },
        {
            pos: [2, 9, 5],
            state: "minecraft:calcite"
        },
        {
            pos: [2, 9, 6],
            state: "minecraft:calcite"
        },
        {
            pos: [2, 9, 7],
            state: "minecraft:calcite"
        },
        {
            pos: [2, 9, 8],
            state: "minecraft:calcite"
        },
        {
            pos: [2, 9, 9],
            state: "minecraft:calcite"
        },
        {
            pos: [2, 9, 10],
            state: "minecraft:calcite"
        },
        {
            pos: [2, 9, 11],
            state: "minecraft:smooth_basalt"
        },
        {
            pos: [3, 9, 2],
            state: "minecraft:smooth_basalt"
        },
        {
            pos: [3, 9, 3],
            state: "minecraft:calcite"
        },
        {
            pos: [3, 9, 4],
            state: "minecraft:calcite"
        },
        {
            pos: [3, 9, 5],
            state: "nodeworks:celestine_block"
        },
        {
            pos: [3, 9, 6],
            state: "nodeworks:celestine_block"
        },
        {
            pos: [3, 9, 7],
            state: "nodeworks:celestine_block"
        },
        {
            pos: [3, 9, 8],
            state: "nodeworks:budding_celestine"
        },
        {
            pos: [3, 9, 9],
            state: "nodeworks:celestine_block"
        },
        {
            pos: [3, 9, 10],
            state: "minecraft:calcite"
        },
        {
            pos: [3, 9, 11],
            state: "minecraft:calcite"
        },
        {
            pos: [3, 9, 12],
            state: "minecraft:smooth_basalt"
        },
        {
            pos: [4, 9, 1],
            state: "minecraft:smooth_basalt"
        },
        {
            pos: [4, 9, 2],
            state: "minecraft:smooth_basalt"
        },
        {
            pos: [4, 9, 3],
            state: "minecraft:calcite"
        },
        {
            pos: [4, 9, 4],
            state: "nodeworks:celestine_block"
        },
        {
            pos: [4, 9, 5],
            state: "nodeworks:celestine_block"
        },
        {
            pos: [4, 9, 9],
            state: "nodeworks:celestine_block"
        },
        {
            pos: [4, 9, 10],
            state: "nodeworks:celestine_block"
        },
        {
            pos: [4, 9, 11],
            state: "minecraft:calcite"
        },
        {
            pos: [4, 9, 12],
            state: "minecraft:smooth_basalt"
        },
        {
            pos: [5, 9, 1],
            state: "minecraft:smooth_basalt"
        },
        {
            pos: [5, 9, 10],
            state: "nodeworks:celestine_block"
        },
        {
            pos: [5, 9, 11],
            state: "minecraft:calcite"
        },
        {
            pos: [5, 9, 12],
            state: "minecraft:calcite"
        },
        {
            pos: [5, 9, 13],
            state: "minecraft:smooth_basalt"
        },
        {
            pos: [6, 9, 10],
            state: "nodeworks:celestine_block"
        },
        {
            pos: [6, 9, 11],
            state: "nodeworks:celestine_block"
        },
        {
            pos: [6, 9, 12],
            state: "minecraft:calcite"
        },
        {
            pos: [6, 9, 13],
            state: "minecraft:smooth_basalt"
        },
        {
            pos: [7, 9, 10],
            state: "nodeworks:celestine_block"
        },
        {
            pos: [7, 9, 11],
            state: "nodeworks:celestine_block"
        },
        {
            pos: [7, 9, 12],
            state: "minecraft:calcite"
        },
        {
            pos: [7, 9, 13],
            state: "minecraft:smooth_basalt"
        },
        {
            pos: [8, 9, 10],
            state: "nodeworks:celestine_block"
        },
        {
            pos: [8, 9, 11],
            state: "minecraft:calcite"
        },
        {
            pos: [8, 9, 12],
            state: "minecraft:smooth_basalt"
        },
        {
            pos: [9, 9, 9],
            state: "nodeworks:celestine_block"
        },
        {
            pos: [9, 9, 10],
            state: "nodeworks:celestine_block"
        },
        {
            pos: [9, 9, 11],
            state: "minecraft:calcite"
        },
        {
            pos: [9, 9, 12],
            state: "minecraft:smooth_basalt"
        },
        {
            pos: [10, 9, 6],
            state: "nodeworks:celestine_block"
        },
        {
            pos: [10, 9, 7],
            state: "nodeworks:celestine_block"
        },
        {
            pos: [10, 9, 8],
            state: "nodeworks:celestine_block"
        },
        {
            pos: [10, 9, 9],
            state: "nodeworks:celestine_block"
        },
        {
            pos: [10, 9, 10],
            state: "minecraft:calcite"
        },
        {
            pos: [10, 9, 11],
            state: "minecraft:smooth_basalt"
        },
        {
            pos: [11, 9, 5],
            state: "minecraft:calcite"
        },
        {
            pos: [11, 9, 6],
            state: "minecraft:calcite"
        },
        {
            pos: [11, 9, 7],
            state: "minecraft:calcite"
        },
        {
            pos: [11, 9, 8],
            state: "minecraft:calcite"
        },
        {
            pos: [11, 9, 9],
            state: "minecraft:calcite"
        },
        {
            pos: [11, 9, 10],
            state: "minecraft:smooth_basalt"
        },
        {
            pos: [12, 9, 3],
            state: "minecraft:smooth_basalt"
        },
        {
            pos: [12, 9, 4],
            state: "minecraft:smooth_basalt"
        },
        {
            pos: [12, 9, 5],
            state: "minecraft:smooth_basalt"
        },
        {
            pos: [12, 9, 6],
            state: "minecraft:calcite"
        },
        {
            pos: [12, 9, 7],
            state: "minecraft:calcite"
        },
        {
            pos: [12, 9, 8],
            state: "minecraft:smooth_basalt"
        },
        {
            pos: [12, 9, 9],
            state: "minecraft:smooth_basalt"
        },
        {
            pos: [13, 9, 4],
            state: "minecraft:stone"
        },
        {
            pos: [13, 9, 5],
            state: "minecraft:smooth_basalt"
        },
        {
            pos: [13, 9, 6],
            state: "minecraft:smooth_basalt"
        },
        {
            pos: [13, 9, 7],
            state: "minecraft:deepslate{axis:y}"
        },
        {
            pos: [1, 10, 5],
            state: "minecraft:smooth_basalt"
        },
        {
            pos: [1, 10, 6],
            state: "minecraft:smooth_basalt"
        },
        {
            pos: [1, 10, 7],
            state: "minecraft:smooth_basalt"
        },
        {
            pos: [1, 10, 8],
            state: "minecraft:smooth_basalt"
        },
        {
            pos: [1, 10, 9],
            state: "minecraft:smooth_basalt"
        },
        {
            pos: [2, 10, 4],
            state: "minecraft:smooth_basalt"
        },
        {
            pos: [2, 10, 5],
            state: "minecraft:smooth_basalt"
        },
        {
            pos: [2, 10, 6],
            state: "minecraft:calcite"
        },
        {
            pos: [2, 10, 7],
            state: "minecraft:calcite"
        },
        {
            pos: [2, 10, 8],
            state: "minecraft:calcite"
        },
        {
            pos: [2, 10, 9],
            state: "minecraft:smooth_basalt"
        },
        {
            pos: [2, 10, 10],
            state: "minecraft:smooth_basalt"
        },
        {
            pos: [2, 10, 11],
            state: "minecraft:smooth_basalt"
        },
        {
            pos: [3, 10, 3],
            state: "minecraft:smooth_basalt"
        },
        {
            pos: [3, 10, 4],
            state: "minecraft:calcite"
        },
        {
            pos: [3, 10, 5],
            state: "minecraft:calcite"
        },
        {
            pos: [3, 10, 6],
            state: "minecraft:calcite"
        },
        {
            pos: [3, 10, 7],
            state: "nodeworks:celestine_block"
        },
        {
            pos: [3, 10, 8],
            state: "minecraft:calcite"
        },
        {
            pos: [3, 10, 9],
            state: "minecraft:calcite"
        },
        {
            pos: [3, 10, 10],
            state: "minecraft:calcite"
        },
        {
            pos: [3, 10, 11],
            state: "minecraft:smooth_basalt"
        },
        {
            pos: [4, 10, 2],
            state: "minecraft:smooth_basalt"
        },
        {
            pos: [4, 10, 3],
            state: "minecraft:calcite"
        },
        {
            pos: [4, 10, 4],
            state: "minecraft:calcite"
        },
        {
            pos: [4, 10, 5],
            state: "nodeworks:celestine_block"
        },
        {
            pos: [4, 10, 6],
            state: "nodeworks:celestine_block"
        },
        {
            pos: [4, 10, 7],
            state: "nodeworks:celestine_block"
        },
        {
            pos: [4, 10, 8],
            state: "nodeworks:celestine_block"
        },
        {
            pos: [4, 10, 9],
            state: "nodeworks:celestine_block"
        },
        {
            pos: [4, 10, 10],
            state: "minecraft:calcite"
        },
        {
            pos: [4, 10, 11],
            state: "minecraft:calcite"
        },
        {
            pos: [4, 10, 12],
            state: "minecraft:smooth_basalt"
        },
        {
            pos: [5, 10, 2],
            state: "minecraft:smooth_basalt"
        },
        {
            pos: [5, 10, 3],
            state: "minecraft:calcite"
        },
        {
            pos: [5, 10, 4],
            state: "nodeworks:celestine_block"
        },
        {
            pos: [5, 10, 5],
            state: "nodeworks:celestine_block"
        },
        {
            pos: [5, 10, 6],
            state: "nodeworks:celestine_block"
        },
        {
            pos: [5, 10, 8],
            state: "nodeworks:celestine_block"
        },
        {
            pos: [5, 10, 9],
            state: "nodeworks:celestine_block"
        },
        {
            pos: [5, 10, 10],
            state: "nodeworks:celestine_block"
        },
        {
            pos: [5, 10, 11],
            state: "minecraft:calcite"
        },
        {
            pos: [5, 10, 12],
            state: "minecraft:smooth_basalt"
        },
        {
            pos: [6, 10, 5],
            state: "nodeworks:celestine_block"
        },
        {
            pos: [6, 10, 9],
            state: "nodeworks:celestine_block"
        },
        {
            pos: [6, 10, 10],
            state: "nodeworks:celestine_block"
        },
        {
            pos: [6, 10, 11],
            state: "minecraft:calcite"
        },
        {
            pos: [6, 10, 12],
            state: "minecraft:smooth_basalt"
        },
        {
            pos: [7, 10, 9],
            state: "nodeworks:celestine_block"
        },
        {
            pos: [7, 10, 10],
            state: "nodeworks:celestine_block"
        },
        {
            pos: [7, 10, 11],
            state: "minecraft:calcite"
        },
        {
            pos: [7, 10, 12],
            state: "minecraft:smooth_basalt"
        },
        {
            pos: [8, 10, 8],
            state: "nodeworks:celestine_block"
        },
        {
            pos: [8, 10, 9],
            state: "nodeworks:celestine_block"
        },
        {
            pos: [8, 10, 10],
            state: "minecraft:calcite"
        },
        {
            pos: [8, 10, 11],
            state: "minecraft:calcite"
        },
        {
            pos: [8, 10, 12],
            state: "minecraft:smooth_basalt"
        },
        {
            pos: [9, 10, 6],
            state: "nodeworks:celestine_block"
        },
        {
            pos: [9, 10, 7],
            state: "nodeworks:celestine_block"
        },
        {
            pos: [9, 10, 8],
            state: "nodeworks:celestine_block"
        },
        {
            pos: [9, 10, 9],
            state: "nodeworks:celestine_block"
        },
        {
            pos: [9, 10, 10],
            state: "minecraft:calcite"
        },
        {
            pos: [9, 10, 11],
            state: "minecraft:smooth_basalt"
        },
        {
            pos: [10, 10, 5],
            state: "minecraft:calcite"
        },
        {
            pos: [10, 10, 6],
            state: "nodeworks:celestine_block"
        },
        {
            pos: [10, 10, 7],
            state: "nodeworks:celestine_block"
        },
        {
            pos: [10, 10, 8],
            state: "minecraft:calcite"
        },
        {
            pos: [10, 10, 9],
            state: "minecraft:calcite"
        },
        {
            pos: [10, 10, 10],
            state: "minecraft:smooth_basalt"
        },
        {
            pos: [10, 10, 11],
            state: "minecraft:smooth_basalt"
        },
        {
            pos: [11, 10, 4],
            state: "minecraft:smooth_basalt"
        },
        {
            pos: [11, 10, 5],
            state: "minecraft:calcite"
        },
        {
            pos: [11, 10, 6],
            state: "minecraft:calcite"
        },
        {
            pos: [11, 10, 7],
            state: "minecraft:calcite"
        },
        {
            pos: [11, 10, 8],
            state: "minecraft:calcite"
        },
        {
            pos: [11, 10, 9],
            state: "minecraft:smooth_basalt"
        },
        {
            pos: [12, 10, 4],
            state: "minecraft:smooth_basalt"
        },
        {
            pos: [12, 10, 5],
            state: "minecraft:smooth_basalt"
        },
        {
            pos: [12, 10, 6],
            state: "minecraft:smooth_basalt"
        },
        {
            pos: [12, 10, 7],
            state: "minecraft:smooth_basalt"
        },
        {
            pos: [12, 10, 8],
            state: "minecraft:smooth_basalt"
        },
        {
            pos: [2, 11, 5],
            state: "minecraft:smooth_basalt"
        },
        {
            pos: [2, 11, 6],
            state: "minecraft:smooth_basalt"
        },
        {
            pos: [2, 11, 7],
            state: "minecraft:smooth_basalt"
        },
        {
            pos: [2, 11, 8],
            state: "minecraft:smooth_basalt"
        },
        {
            pos: [2, 11, 9],
            state: "minecraft:smooth_basalt"
        },
        {
            pos: [3, 11, 4],
            state: "minecraft:smooth_basalt"
        },
        {
            pos: [3, 11, 5],
            state: "minecraft:smooth_basalt"
        },
        {
            pos: [3, 11, 6],
            state: "minecraft:calcite"
        },
        {
            pos: [3, 11, 7],
            state: "minecraft:calcite"
        },
        {
            pos: [3, 11, 8],
            state: "minecraft:calcite"
        },
        {
            pos: [3, 11, 9],
            state: "minecraft:smooth_basalt"
        },
        {
            pos: [3, 11, 10],
            state: "minecraft:smooth_basalt"
        },
        {
            pos: [4, 11, 3],
            state: "minecraft:smooth_basalt"
        },
        {
            pos: [4, 11, 4],
            state: "minecraft:smooth_basalt"
        },
        {
            pos: [4, 11, 5],
            state: "minecraft:calcite"
        },
        {
            pos: [4, 11, 6],
            state: "minecraft:calcite"
        },
        {
            pos: [4, 11, 7],
            state: "minecraft:calcite"
        },
        {
            pos: [4, 11, 8],
            state: "minecraft:calcite"
        },
        {
            pos: [4, 11, 9],
            state: "minecraft:calcite"
        },
        {
            pos: [4, 11, 10],
            state: "minecraft:smooth_basalt"
        },
        {
            pos: [4, 11, 11],
            state: "minecraft:smooth_basalt"
        },
        {
            pos: [5, 11, 2],
            state: "minecraft:smooth_basalt"
        },
        {
            pos: [5, 11, 3],
            state: "minecraft:smooth_basalt"
        },
        {
            pos: [5, 11, 4],
            state: "minecraft:calcite"
        },
        {
            pos: [5, 11, 5],
            state: "minecraft:calcite"
        },
        {
            pos: [5, 11, 6],
            state: "nodeworks:celestine_block"
        },
        {
            pos: [5, 11, 7],
            state: "nodeworks:celestine_block"
        },
        {
            pos: [5, 11, 8],
            state: "nodeworks:celestine_block"
        },
        {
            pos: [5, 11, 9],
            state: "minecraft:calcite"
        },
        {
            pos: [5, 11, 10],
            state: "minecraft:calcite"
        },
        {
            pos: [5, 11, 11],
            state: "minecraft:smooth_basalt"
        },
        {
            pos: [6, 11, 2],
            state: "minecraft:smooth_basalt"
        },
        {
            pos: [6, 11, 3],
            state: "minecraft:smooth_basalt"
        },
        {
            pos: [6, 11, 4],
            state: "minecraft:calcite"
        },
        {
            pos: [6, 11, 5],
            state: "nodeworks:celestine_block"
        },
        {
            pos: [6, 11, 6],
            state: "nodeworks:celestine_block"
        },
        {
            pos: [6, 11, 7],
            state: "nodeworks:celestine_block"
        },
        {
            pos: [6, 11, 8],
            state: "nodeworks:celestine_block"
        },
        {
            pos: [6, 11, 9],
            state: "minecraft:calcite"
        },
        {
            pos: [6, 11, 10],
            state: "minecraft:calcite"
        },
        {
            pos: [6, 11, 11],
            state: "minecraft:smooth_basalt"
        },
        {
            pos: [7, 11, 5],
            state: "nodeworks:celestine_block"
        },
        {
            pos: [7, 11, 6],
            state: "nodeworks:celestine_block"
        },
        {
            pos: [7, 11, 7],
            state: "nodeworks:celestine_block"
        },
        {
            pos: [7, 11, 8],
            state: "nodeworks:celestine_block"
        },
        {
            pos: [7, 11, 9],
            state: "minecraft:calcite"
        },
        {
            pos: [7, 11, 10],
            state: "minecraft:calcite"
        },
        {
            pos: [7, 11, 11],
            state: "minecraft:smooth_basalt"
        },
        {
            pos: [8, 11, 5],
            state: "minecraft:calcite"
        },
        {
            pos: [8, 11, 6],
            state: "nodeworks:celestine_block"
        },
        {
            pos: [8, 11, 7],
            state: "nodeworks:celestine_block"
        },
        {
            pos: [8, 11, 8],
            state: "nodeworks:celestine_block"
        },
        {
            pos: [8, 11, 9],
            state: "minecraft:calcite"
        },
        {
            pos: [8, 11, 10],
            state: "minecraft:calcite"
        },
        {
            pos: [8, 11, 11],
            state: "minecraft:smooth_basalt"
        },
        {
            pos: [9, 11, 5],
            state: "minecraft:calcite"
        },
        {
            pos: [9, 11, 6],
            state: "minecraft:calcite"
        },
        {
            pos: [9, 11, 7],
            state: "minecraft:calcite"
        },
        {
            pos: [9, 11, 8],
            state: "minecraft:calcite"
        },
        {
            pos: [9, 11, 9],
            state: "minecraft:calcite"
        },
        {
            pos: [9, 11, 10],
            state: "minecraft:smooth_basalt"
        },
        {
            pos: [10, 11, 3],
            state: "minecraft:smooth_basalt"
        },
        {
            pos: [10, 11, 4],
            state: "minecraft:smooth_basalt"
        },
        {
            pos: [10, 11, 5],
            state: "minecraft:calcite"
        },
        {
            pos: [10, 11, 6],
            state: "minecraft:calcite"
        },
        {
            pos: [10, 11, 7],
            state: "minecraft:calcite"
        },
        {
            pos: [10, 11, 8],
            state: "minecraft:smooth_basalt"
        },
        {
            pos: [10, 11, 9],
            state: "minecraft:smooth_basalt"
        },
        {
            pos: [11, 11, 4],
            state: "minecraft:smooth_basalt"
        },
        {
            pos: [11, 11, 5],
            state: "minecraft:smooth_basalt"
        },
        {
            pos: [11, 11, 6],
            state: "minecraft:smooth_basalt"
        },
        {
            pos: [11, 11, 7],
            state: "minecraft:smooth_basalt"
        },
        {
            pos: [11, 11, 8],
            state: "minecraft:smooth_basalt"
        },
        {
            pos: [3, 12, 6],
            state: "minecraft:smooth_basalt"
        },
        {
            pos: [3, 12, 7],
            state: "minecraft:smooth_basalt"
        },
        {
            pos: [3, 12, 8],
            state: "minecraft:smooth_basalt"
        },
        {
            pos: [4, 12, 5],
            state: "minecraft:smooth_basalt"
        },
        {
            pos: [4, 12, 6],
            state: "minecraft:smooth_basalt"
        },
        {
            pos: [4, 12, 7],
            state: "minecraft:smooth_basalt"
        },
        {
            pos: [4, 12, 8],
            state: "minecraft:smooth_basalt"
        },
        {
            pos: [4, 12, 9],
            state: "minecraft:smooth_basalt"
        },
        {
            pos: [5, 12, 4],
            state: "minecraft:smooth_basalt"
        },
        {
            pos: [5, 12, 5],
            state: "minecraft:smooth_basalt"
        },
        {
            pos: [5, 12, 6],
            state: "minecraft:calcite"
        },
        {
            pos: [5, 12, 7],
            state: "minecraft:calcite"
        },
        {
            pos: [5, 12, 8],
            state: "minecraft:smooth_basalt"
        },
        {
            pos: [5, 12, 9],
            state: "minecraft:smooth_basalt"
        },
        {
            pos: [5, 12, 10],
            state: "minecraft:smooth_basalt"
        },
        {
            pos: [6, 12, 4],
            state: "minecraft:smooth_basalt"
        },
        {
            pos: [6, 12, 5],
            state: "minecraft:smooth_basalt"
        },
        {
            pos: [6, 12, 6],
            state: "minecraft:calcite"
        },
        {
            pos: [6, 12, 7],
            state: "minecraft:calcite"
        },
        {
            pos: [6, 12, 8],
            state: "minecraft:calcite"
        },
        {
            pos: [6, 12, 9],
            state: "minecraft:smooth_basalt"
        },
        {
            pos: [6, 12, 10],
            state: "minecraft:smooth_basalt"
        },
        {
            pos: [7, 12, 3],
            state: "minecraft:smooth_basalt"
        },
        {
            pos: [7, 12, 4],
            state: "minecraft:smooth_basalt"
        },
        {
            pos: [7, 12, 5],
            state: "minecraft:smooth_basalt"
        },
        {
            pos: [7, 12, 6],
            state: "minecraft:calcite"
        },
        {
            pos: [7, 12, 7],
            state: "minecraft:calcite"
        },
        {
            pos: [7, 12, 8],
            state: "minecraft:calcite"
        },
        {
            pos: [7, 12, 9],
            state: "minecraft:smooth_basalt"
        },
        {
            pos: [7, 12, 10],
            state: "minecraft:smooth_basalt"
        },
        {
            pos: [8, 12, 4],
            state: "minecraft:smooth_basalt"
        },
        {
            pos: [8, 12, 5],
            state: "minecraft:smooth_basalt"
        },
        {
            pos: [8, 12, 6],
            state: "minecraft:calcite"
        },
        {
            pos: [8, 12, 7],
            state: "minecraft:calcite"
        },
        {
            pos: [8, 12, 8],
            state: "minecraft:smooth_basalt"
        },
        {
            pos: [8, 12, 9],
            state: "minecraft:smooth_basalt"
        },
        {
            pos: [9, 12, 4],
            state: "minecraft:smooth_basalt"
        },
        {
            pos: [9, 12, 5],
            state: "minecraft:smooth_basalt"
        },
        {
            pos: [9, 12, 6],
            state: "minecraft:smooth_basalt"
        },
        {
            pos: [9, 12, 7],
            state: "minecraft:smooth_basalt"
        },
        {
            pos: [9, 12, 8],
            state: "minecraft:smooth_basalt"
        },
        {
            pos: [10, 12, 5],
            state: "minecraft:smooth_basalt"
        },
        {
            pos: [10, 12, 6],
            state: "minecraft:smooth_basalt"
        },
        {
            pos: [0, 0, 0],
            state: "minecraft:air"
        },
        {
            pos: [0, 0, 1],
            state: "minecraft:air"
        },
        {
            pos: [0, 0, 2],
            state: "minecraft:air"
        },
        {
            pos: [0, 0, 3],
            state: "minecraft:air"
        },
        {
            pos: [0, 0, 4],
            state: "minecraft:air"
        },
        {
            pos: [0, 0, 5],
            state: "minecraft:air"
        },
        {
            pos: [0, 0, 6],
            state: "minecraft:air"
        },
        {
            pos: [0, 0, 7],
            state: "minecraft:air"
        },
        {
            pos: [0, 0, 8],
            state: "minecraft:air"
        },
        {
            pos: [0, 0, 9],
            state: "minecraft:air"
        },
        {
            pos: [0, 0, 10],
            state: "minecraft:air"
        },
        {
            pos: [0, 0, 11],
            state: "minecraft:air"
        },
        {
            pos: [0, 0, 12],
            state: "minecraft:air"
        },
        {
            pos: [0, 0, 13],
            state: "minecraft:air"
        },
        {
            pos: [1, 0, 0],
            state: "minecraft:air"
        },
        {
            pos: [1, 0, 1],
            state: "minecraft:air"
        },
        {
            pos: [1, 0, 2],
            state: "minecraft:air"
        },
        {
            pos: [1, 0, 3],
            state: "minecraft:air"
        },
        {
            pos: [1, 0, 4],
            state: "minecraft:air"
        },
        {
            pos: [1, 0, 5],
            state: "minecraft:air"
        },
        {
            pos: [1, 0, 6],
            state: "minecraft:air"
        },
        {
            pos: [1, 0, 7],
            state: "minecraft:air"
        },
        {
            pos: [1, 0, 8],
            state: "minecraft:air"
        },
        {
            pos: [1, 0, 9],
            state: "minecraft:air"
        },
        {
            pos: [1, 0, 10],
            state: "minecraft:air"
        },
        {
            pos: [1, 0, 11],
            state: "minecraft:air"
        },
        {
            pos: [1, 0, 12],
            state: "minecraft:air"
        },
        {
            pos: [1, 0, 13],
            state: "minecraft:air"
        },
        {
            pos: [2, 0, 0],
            state: "minecraft:air"
        },
        {
            pos: [2, 0, 1],
            state: "minecraft:air"
        },
        {
            pos: [2, 0, 2],
            state: "minecraft:air"
        },
        {
            pos: [2, 0, 3],
            state: "minecraft:air"
        },
        {
            pos: [2, 0, 4],
            state: "minecraft:air"
        },
        {
            pos: [2, 0, 5],
            state: "minecraft:air"
        },
        {
            pos: [2, 0, 6],
            state: "minecraft:air"
        },
        {
            pos: [2, 0, 7],
            state: "minecraft:air"
        },
        {
            pos: [2, 0, 8],
            state: "minecraft:air"
        },
        {
            pos: [2, 0, 9],
            state: "minecraft:air"
        },
        {
            pos: [2, 0, 10],
            state: "minecraft:air"
        },
        {
            pos: [2, 0, 11],
            state: "minecraft:air"
        },
        {
            pos: [2, 0, 12],
            state: "minecraft:air"
        },
        {
            pos: [2, 0, 13],
            state: "minecraft:air"
        },
        {
            pos: [3, 0, 0],
            state: "minecraft:air"
        },
        {
            pos: [3, 0, 1],
            state: "minecraft:air"
        },
        {
            pos: [3, 0, 2],
            state: "minecraft:air"
        },
        {
            pos: [3, 0, 3],
            state: "minecraft:air"
        },
        {
            pos: [3, 0, 4],
            state: "minecraft:air"
        },
        {
            pos: [3, 0, 5],
            state: "minecraft:air"
        },
        {
            pos: [3, 0, 6],
            state: "minecraft:air"
        },
        {
            pos: [3, 0, 7],
            state: "minecraft:air"
        },
        {
            pos: [3, 0, 8],
            state: "minecraft:air"
        },
        {
            pos: [3, 0, 9],
            state: "minecraft:air"
        },
        {
            pos: [3, 0, 10],
            state: "minecraft:air"
        },
        {
            pos: [3, 0, 11],
            state: "minecraft:air"
        },
        {
            pos: [3, 0, 12],
            state: "minecraft:air"
        },
        {
            pos: [3, 0, 13],
            state: "minecraft:air"
        },
        {
            pos: [4, 0, 0],
            state: "minecraft:air"
        },
        {
            pos: [4, 0, 1],
            state: "minecraft:air"
        },
        {
            pos: [4, 0, 2],
            state: "minecraft:air"
        },
        {
            pos: [4, 0, 3],
            state: "minecraft:air"
        },
        {
            pos: [4, 0, 4],
            state: "minecraft:air"
        },
        {
            pos: [4, 0, 5],
            state: "minecraft:air"
        },
        {
            pos: [4, 0, 6],
            state: "minecraft:air"
        },
        {
            pos: [4, 0, 7],
            state: "minecraft:air"
        },
        {
            pos: [4, 0, 8],
            state: "minecraft:air"
        },
        {
            pos: [4, 0, 9],
            state: "minecraft:air"
        },
        {
            pos: [4, 0, 10],
            state: "minecraft:air"
        },
        {
            pos: [4, 0, 11],
            state: "minecraft:air"
        },
        {
            pos: [4, 0, 12],
            state: "minecraft:air"
        },
        {
            pos: [4, 0, 13],
            state: "minecraft:air"
        },
        {
            pos: [5, 0, 0],
            state: "minecraft:air"
        },
        {
            pos: [5, 0, 1],
            state: "minecraft:air"
        },
        {
            pos: [5, 0, 2],
            state: "minecraft:air"
        },
        {
            pos: [5, 0, 3],
            state: "minecraft:air"
        },
        {
            pos: [5, 0, 4],
            state: "minecraft:air"
        },
        {
            pos: [5, 0, 5],
            state: "minecraft:air"
        },
        {
            pos: [5, 0, 6],
            state: "minecraft:air"
        },
        {
            pos: [5, 0, 7],
            state: "minecraft:air"
        },
        {
            pos: [5, 0, 8],
            state: "minecraft:air"
        },
        {
            pos: [5, 0, 9],
            state: "minecraft:air"
        },
        {
            pos: [5, 0, 10],
            state: "minecraft:air"
        },
        {
            pos: [5, 0, 11],
            state: "minecraft:air"
        },
        {
            pos: [5, 0, 12],
            state: "minecraft:air"
        },
        {
            pos: [5, 0, 13],
            state: "minecraft:air"
        },
        {
            pos: [6, 0, 0],
            state: "minecraft:air"
        },
        {
            pos: [6, 0, 1],
            state: "minecraft:air"
        },
        {
            pos: [6, 0, 2],
            state: "minecraft:air"
        },
        {
            pos: [6, 0, 3],
            state: "minecraft:air"
        },
        {
            pos: [6, 0, 4],
            state: "minecraft:air"
        },
        {
            pos: [6, 0, 5],
            state: "minecraft:air"
        },
        {
            pos: [6, 0, 9],
            state: "minecraft:air"
        },
        {
            pos: [6, 0, 10],
            state: "minecraft:air"
        },
        {
            pos: [6, 0, 11],
            state: "minecraft:air"
        },
        {
            pos: [6, 0, 12],
            state: "minecraft:air"
        },
        {
            pos: [6, 0, 13],
            state: "minecraft:air"
        },
        {
            pos: [7, 0, 0],
            state: "minecraft:air"
        },
        {
            pos: [7, 0, 1],
            state: "minecraft:air"
        },
        {
            pos: [7, 0, 2],
            state: "minecraft:air"
        },
        {
            pos: [7, 0, 3],
            state: "minecraft:air"
        },
        {
            pos: [7, 0, 4],
            state: "minecraft:air"
        },
        {
            pos: [7, 0, 5],
            state: "minecraft:air"
        },
        {
            pos: [7, 0, 9],
            state: "minecraft:air"
        },
        {
            pos: [7, 0, 10],
            state: "minecraft:air"
        },
        {
            pos: [7, 0, 11],
            state: "minecraft:air"
        },
        {
            pos: [7, 0, 12],
            state: "minecraft:air"
        },
        {
            pos: [7, 0, 13],
            state: "minecraft:air"
        },
        {
            pos: [8, 0, 0],
            state: "minecraft:air"
        },
        {
            pos: [8, 0, 1],
            state: "minecraft:air"
        },
        {
            pos: [8, 0, 2],
            state: "minecraft:air"
        },
        {
            pos: [8, 0, 3],
            state: "minecraft:air"
        },
        {
            pos: [8, 0, 4],
            state: "minecraft:air"
        },
        {
            pos: [8, 0, 5],
            state: "minecraft:air"
        },
        {
            pos: [8, 0, 8],
            state: "minecraft:air"
        },
        {
            pos: [8, 0, 9],
            state: "minecraft:air"
        },
        {
            pos: [8, 0, 10],
            state: "minecraft:air"
        },
        {
            pos: [8, 0, 11],
            state: "minecraft:air"
        },
        {
            pos: [8, 0, 12],
            state: "minecraft:air"
        },
        {
            pos: [8, 0, 13],
            state: "minecraft:air"
        },
        {
            pos: [9, 0, 0],
            state: "minecraft:air"
        },
        {
            pos: [9, 0, 1],
            state: "minecraft:air"
        },
        {
            pos: [9, 0, 2],
            state: "minecraft:air"
        },
        {
            pos: [9, 0, 3],
            state: "minecraft:air"
        },
        {
            pos: [9, 0, 4],
            state: "minecraft:air"
        },
        {
            pos: [9, 0, 5],
            state: "minecraft:air"
        },
        {
            pos: [9, 0, 6],
            state: "minecraft:air"
        },
        {
            pos: [9, 0, 7],
            state: "minecraft:air"
        },
        {
            pos: [9, 0, 8],
            state: "minecraft:air"
        },
        {
            pos: [9, 0, 9],
            state: "minecraft:air"
        },
        {
            pos: [9, 0, 10],
            state: "minecraft:air"
        },
        {
            pos: [9, 0, 11],
            state: "minecraft:air"
        },
        {
            pos: [9, 0, 12],
            state: "minecraft:air"
        },
        {
            pos: [9, 0, 13],
            state: "minecraft:air"
        },
        {
            pos: [10, 0, 0],
            state: "minecraft:air"
        },
        {
            pos: [10, 0, 1],
            state: "minecraft:air"
        },
        {
            pos: [10, 0, 2],
            state: "minecraft:air"
        },
        {
            pos: [10, 0, 3],
            state: "minecraft:air"
        },
        {
            pos: [10, 0, 4],
            state: "minecraft:air"
        },
        {
            pos: [10, 0, 5],
            state: "minecraft:air"
        },
        {
            pos: [10, 0, 6],
            state: "minecraft:air"
        },
        {
            pos: [10, 0, 7],
            state: "minecraft:air"
        },
        {
            pos: [10, 0, 8],
            state: "minecraft:air"
        },
        {
            pos: [10, 0, 9],
            state: "minecraft:air"
        },
        {
            pos: [10, 0, 10],
            state: "minecraft:air"
        },
        {
            pos: [10, 0, 11],
            state: "minecraft:air"
        },
        {
            pos: [10, 0, 12],
            state: "minecraft:air"
        },
        {
            pos: [10, 0, 13],
            state: "minecraft:air"
        },
        {
            pos: [11, 0, 0],
            state: "minecraft:air"
        },
        {
            pos: [11, 0, 1],
            state: "minecraft:air"
        },
        {
            pos: [11, 0, 2],
            state: "minecraft:air"
        },
        {
            pos: [11, 0, 3],
            state: "minecraft:air"
        },
        {
            pos: [11, 0, 4],
            state: "minecraft:air"
        },
        {
            pos: [11, 0, 5],
            state: "minecraft:air"
        },
        {
            pos: [11, 0, 6],
            state: "minecraft:air"
        },
        {
            pos: [11, 0, 7],
            state: "minecraft:air"
        },
        {
            pos: [11, 0, 8],
            state: "minecraft:air"
        },
        {
            pos: [11, 0, 9],
            state: "minecraft:air"
        },
        {
            pos: [11, 0, 10],
            state: "minecraft:air"
        },
        {
            pos: [11, 0, 11],
            state: "minecraft:air"
        },
        {
            pos: [11, 0, 12],
            state: "minecraft:air"
        },
        {
            pos: [11, 0, 13],
            state: "minecraft:air"
        },
        {
            pos: [12, 0, 0],
            state: "minecraft:air"
        },
        {
            pos: [12, 0, 1],
            state: "minecraft:air"
        },
        {
            pos: [12, 0, 2],
            state: "minecraft:air"
        },
        {
            pos: [12, 0, 3],
            state: "minecraft:air"
        },
        {
            pos: [12, 0, 4],
            state: "minecraft:air"
        },
        {
            pos: [12, 0, 5],
            state: "minecraft:air"
        },
        {
            pos: [12, 0, 6],
            state: "minecraft:air"
        },
        {
            pos: [12, 0, 7],
            state: "minecraft:air"
        },
        {
            pos: [12, 0, 8],
            state: "minecraft:air"
        },
        {
            pos: [12, 0, 9],
            state: "minecraft:air"
        },
        {
            pos: [12, 0, 10],
            state: "minecraft:air"
        },
        {
            pos: [12, 0, 11],
            state: "minecraft:air"
        },
        {
            pos: [12, 0, 12],
            state: "minecraft:air"
        },
        {
            pos: [12, 0, 13],
            state: "minecraft:air"
        },
        {
            pos: [13, 0, 0],
            state: "minecraft:air"
        },
        {
            pos: [13, 0, 1],
            state: "minecraft:air"
        },
        {
            pos: [13, 0, 2],
            state: "minecraft:air"
        },
        {
            pos: [13, 0, 3],
            state: "minecraft:air"
        },
        {
            pos: [13, 0, 4],
            state: "minecraft:air"
        },
        {
            pos: [13, 0, 5],
            state: "minecraft:air"
        },
        {
            pos: [13, 0, 6],
            state: "minecraft:air"
        },
        {
            pos: [13, 0, 7],
            state: "minecraft:air"
        },
        {
            pos: [13, 0, 8],
            state: "minecraft:air"
        },
        {
            pos: [13, 0, 9],
            state: "minecraft:air"
        },
        {
            pos: [13, 0, 10],
            state: "minecraft:air"
        },
        {
            pos: [13, 0, 11],
            state: "minecraft:air"
        },
        {
            pos: [13, 0, 12],
            state: "minecraft:air"
        },
        {
            pos: [13, 0, 13],
            state: "minecraft:air"
        },
        {
            pos: [0, 1, 0],
            state: "minecraft:air"
        },
        {
            pos: [0, 1, 1],
            state: "minecraft:air"
        },
        {
            pos: [0, 1, 2],
            state: "minecraft:air"
        },
        {
            pos: [0, 1, 3],
            state: "minecraft:air"
        },
        {
            pos: [0, 1, 4],
            state: "minecraft:air"
        },
        {
            pos: [0, 1, 5],
            state: "minecraft:air"
        },
        {
            pos: [0, 1, 6],
            state: "minecraft:air"
        },
        {
            pos: [0, 1, 7],
            state: "minecraft:air"
        },
        {
            pos: [0, 1, 8],
            state: "minecraft:air"
        },
        {
            pos: [0, 1, 9],
            state: "minecraft:air"
        },
        {
            pos: [0, 1, 10],
            state: "minecraft:air"
        },
        {
            pos: [0, 1, 11],
            state: "minecraft:air"
        },
        {
            pos: [0, 1, 12],
            state: "minecraft:air"
        },
        {
            pos: [0, 1, 13],
            state: "minecraft:air"
        },
        {
            pos: [1, 1, 0],
            state: "minecraft:air"
        },
        {
            pos: [1, 1, 1],
            state: "minecraft:air"
        },
        {
            pos: [1, 1, 2],
            state: "minecraft:air"
        },
        {
            pos: [1, 1, 3],
            state: "minecraft:air"
        },
        {
            pos: [1, 1, 4],
            state: "minecraft:air"
        },
        {
            pos: [1, 1, 5],
            state: "minecraft:air"
        },
        {
            pos: [1, 1, 6],
            state: "minecraft:air"
        },
        {
            pos: [1, 1, 7],
            state: "minecraft:air"
        },
        {
            pos: [1, 1, 8],
            state: "minecraft:air"
        },
        {
            pos: [1, 1, 9],
            state: "minecraft:air"
        },
        {
            pos: [1, 1, 10],
            state: "minecraft:air"
        },
        {
            pos: [1, 1, 11],
            state: "minecraft:air"
        },
        {
            pos: [1, 1, 12],
            state: "minecraft:air"
        },
        {
            pos: [1, 1, 13],
            state: "minecraft:air"
        },
        {
            pos: [2, 1, 0],
            state: "minecraft:air"
        },
        {
            pos: [2, 1, 1],
            state: "minecraft:air"
        },
        {
            pos: [2, 1, 2],
            state: "minecraft:air"
        },
        {
            pos: [2, 1, 3],
            state: "minecraft:air"
        },
        {
            pos: [2, 1, 4],
            state: "minecraft:air"
        },
        {
            pos: [2, 1, 5],
            state: "minecraft:air"
        },
        {
            pos: [2, 1, 6],
            state: "minecraft:air"
        },
        {
            pos: [2, 1, 7],
            state: "minecraft:air"
        },
        {
            pos: [2, 1, 8],
            state: "minecraft:air"
        },
        {
            pos: [2, 1, 9],
            state: "minecraft:air"
        },
        {
            pos: [2, 1, 10],
            state: "minecraft:air"
        },
        {
            pos: [2, 1, 11],
            state: "minecraft:air"
        },
        {
            pos: [2, 1, 12],
            state: "minecraft:air"
        },
        {
            pos: [2, 1, 13],
            state: "minecraft:air"
        },
        {
            pos: [3, 1, 0],
            state: "minecraft:air"
        },
        {
            pos: [3, 1, 1],
            state: "minecraft:air"
        },
        {
            pos: [3, 1, 2],
            state: "minecraft:air"
        },
